<sdf version='1.6'>
  <model name='romi'>
    <link name='chassis'>
      <pose frame=''>0 0 0 0 -0 0</pose>
      <inertial>
        <pose frame=''>0 0 0 0 -0 0</pose>
        <mass>0.16</mass>
        <inertia>
          <ixx>0.1</ixx>
          <ixy>0</ixy>
          <ixz>0</ixz>
          <iyy>0.1</iyy>
          <iyz>0</iyz>
          <izz>0.1</izz>
        </inertia>
      </inertial>
      <collision name='chassis_collision_collision'>
        <pose frame=''>0 0 0 0 -0 0</pose>
        <geometry>
          <cylinder>
            <length>0.0195</length>
            <radius>0.0815</radius>
          </cylinder>
        </geometry>
      </collision>
      <collision name='chassis_fixed_joint_lump__caster_front_collision_collision_1'>
        <pose frame=''>0 0 0 0 -0 0</pose>
        <geometry>
          <cylinder>
            <length>0.029</length>
            <radius>0.0254</radius>
          </cylinder>
        </geometry>
      </collision>
      <collision name='chassis_fixed_joint_lump__caster_ball_front_collision_collision_2'>
        <pose frame=''>0 0 0 0 -0 0</pose>
        <geometry>
          <sphere>
            <radius>0.0127</radius>
          </sphere>
        </geometry>
      </collision>
      <collision name='chassis_fixed_joint_lump__caster_back_collision_collision_3'>
        <pose frame=''>0 0 0 0 -0 0</pose>
        <geometry>
          <cylinder>
            <length>0.029</length>
            <radius>0.0254</radius>
          </cylinder>
        </geometry>
      </collision>
      <collision name='chassis_fixed_joint_lump__caster_back_collision_collision_4'>
        <pose frame=''>0 0 0 0 -0 0</pose>
        <geometry>
          <cylinder>
            <length>0.029</length>
            <radius>0.0254</radius>
          </cylinder>
        </geometry>
      </collision>
      <visual name='chassis_visual_visual'>
        <pose frame=''>0 0 0 0 -0 0</pose>
        <geometry>
          <mesh>
            <scale>1 1 1</scale>
            <uri>model://romi/meshes/romi_base.dae</uri>
          </mesh>
        </geometry>
      </visual>
    </link>
    <link name='wheel_l'>
      <pose frame=''>0 0 0 0 -0 0</pose>
      <inertial>
        <pose frame=''>0 0 0 0 -0 0</pose>
        <mass>0.141748</mass>
        <inertia>
          <ixx>4.41663e-05</ixx>
          <ixy>0</ixy>
          <ixz>0</ixz>
          <iyy>4.41663e-05</iyy>
          <iyz>0</iyz>
          <izz>8.68207e-05</izz>
        </inertia>
      </inertial>
      <collision name='wheel_l_collision_collision'>
        <pose frame=''>0 0 0 0 -0 0</pose>
        <geometry>
          <cylinder>
            <length>0.008</length>
            <radius>0.035</radius>
          </cylinder>
        </geometry>
        <surface>
          <contact>
            <ode/>
          </contact>
          <friction>
            <ode>
              <mu>0</mu>
              <mu2>0</mu2>
            </ode>
          </friction>
        </surface>
      </collision>
      <visual name='wheel_l_visual_visual'>
        <pose frame=''>0 0 0 0 -0 0</pose>
        <geometry>
          <mesh>
            <scale>1 1 1</scale>
            <uri>model://romi/meshes/romi_wheel_left.dae</uri>
          </mesh>
        </geometry>
        <material>
          <script>
            <uri>__default__</uri>
            <name>__default__</name>
          </script>
        </material>
      </visual>
      <gravity>1</gravity>
      <velocity_decay/>
    </link>
    <joint name='wheel_l_joint' type='revolute'>
      <child>wheel_l</child>
      <parent>chassis</parent>
      <axis>
        <xyz>0 0 1</xyz>
        <limit>
          <lower>-1e+16</lower>
          <upper>1e+16</upper>
        </limit>
        <dynamics>
          <spring_reference>0</spring_reference>
          <spring_stiffness>0</spring_stiffness>
        </dynamics>
        <use_parent_model_frame>1</use_parent_model_frame>
      </axis>
    </joint>
    <link name='wheel_r'>
      <pose frame=''>0 0 0 0 -0 0</pose>
      <inertial>
        <pose frame=''>0 0 0 0 -0 0</pose>
        <mass>0.141748</mass>
        <inertia>
          <ixx>4.41663e-05</ixx>
          <ixy>0</ixy>
          <ixz>0</ixz>
          <iyy>4.41663e-05</iyy>
          <iyz>0</iyz>
          <izz>8.68207e-05</izz>
        </inertia>
      </inertial>
      <collision name='wheel_r_collision_collision'>
        <pose frame=''>0 0 0 0 -0 0</pose>
        <geometry>
          <cylinder>
            <length>0.008</length>
            <radius>0.035</radius>
          </cylinder>
        </geometry>
        <surface>
          <contact>
            <ode/>
          </contact>
          <friction>
            <ode>
              <mu>0</mu>
              <mu2>0</mu2>
            </ode>
          </friction>
        </surface>
      </collision>
      <visual name='wheel_r_visual_visual'>
        <pose frame=''>0 0 0 0 -0 0</pose>
        <geometry>
          <mesh>
            <scale>1 1 1</scale>
            <uri>model://romi/meshes/romi_wheel_right.dae</uri>
          </mesh>
        </geometry>
        <material>
          <script>
            <uri>__default__</uri>
            <name>__default__</name>
          </script>
        </material>
      </visual>
      <gravity>1</gravity>
      <velocity_decay/>
    </link>
    <joint name='wheel_r_joint' type='revolute'>
      <child>wheel_r</child>
      <parent>chassis</parent>
      <axis>
        <xyz>0 0 1</xyz>
        <limit>
          <lower>-1e+16</lower>
          <upper>1e+16</upper>
        </limit>
        <dynamics>
          <spring_reference>0</spring_reference>
          <spring_stiffness>0</spring_stiffness>
        </dynamics>
        <use_parent_model_frame>1</use_parent_model_frame>
      </axis>
    </joint>
    <static>0</static>
    <plugin name='gazebo_ros_control' filename='libgazebo_ros_control.so'>
      <robotNamespace>/</robotNamespace>
    </plugin>
  </model>
</sdf>
